Workbook
Name distance_to_customer: #REF!
Name distance_to_customer: #REF!
Name heat_pump_factor: 'Materials and energy'!$B$64
Name lifetime: #REF!
Name lifetime: #REF!
Name lifetime: #REF!
Name lifetime_concrete: 'Materials and energy'!$B$25
Name lifetime_SICUT: 'Materials and energy'!$B$27
Name lifetime_wood: 'Materials and energy'!$B$26
Name list_electricity: #REF!
Name list_electricity: #REF!
Name list_electricity: #REF!
Name list_electricity: #REF!
Name milling_electricity: #REF!
Name milling_electricity: #REF!

Sheet Overview
A1: Overview
B45: Holzschwelle | C45: Holzschwelle | D45: Holzschwelle | E45: =RP_wood!O3 -> wo_04 | F45: =RP_wood!R3 -> wo_05 | G45: =RP_wood!U3 -> wo_06 | H45: Betonschwelle | I45: Betonschwelle | J45: =RP_concrete!L3 -> co_03 | K45: =RP_concrete!O3 -> co_04 | L45: =RP_concrete!R3 -> co_05 | M45: SICUT | N45: SICUT | O45: SICUT | P45: SICUT | Q45: SICUT
B46: Basis Szenario, 25 Jahre Nutzung | C46: Szenario Hohen Sägeverluste, 25 Jahre Nutzung | D46: Optimiertes Szenario, 25 Jahre Nutzung | E46: =RP_wood!O4 -> Charles idea | H46: Basis Senario, 40 Jahre Nutzung | I46: Optimiertes Szenario, 40 Jahre Nutzung | M46: Basis Szenario, 20 Jahre Nutzung | N46: Optimiertes Szenario, 20 Jahre Nutzung | O46: Optimiertes Szenario, 30 Jahre Nutzung | P46: Optimiertes Szenario, 40 Jahre Nutzung | Q46: Basis Szenario, 40 Jahre Nutzung
A47: Hauptmaterial 1 | B47: =RP_wood!G10 -> 9.8466667e-13 | C47: =RP_wood!J10 -> 1.19e-12 | D47: =RP_wood!M10 -> 9.8466667e-13 | E47: =RP_wood!P10 -> 1.0266667e-12 | H47: =RP_concrete!G10 -> 2.5957925e-12 | I47: =RP_concrete!J10 -> 2.1121044e-12 | M47: =RP_SICUT!G10 -> 9.2134869e-12 | N47: =RP_SICUT!J10 -> 1.0034491e-12 | O47: =RP_SICUT!M10 -> 6.6896604e-13 | P47: =RP_SICUT!P10 -> 5.0172453e-13 | Q47: =RP_SICUT!S10 -> 4.6067434e-12
A48: Hauptmaterial 2 | H48: =RP_concrete!G11 -> 1.5601221e-14 | I48: =RP_concrete!J11 -> 2.7980451e-15
A49: Bewehrung | H49: =RP_concrete!G12 -> 3.5753622e-13 | I49: =RP_concrete!J12 -> 9.5150769e-14 | N49: =RP_SICUT!J11 -> 4.7791108e-13 | O49: =RP_SICUT!M11 -> 3.1860739e-13 | P49: =RP_SICUT!P11 -> 2.3895554e-13 | Q49: =RP_SICUT!S11 -> 1.3224389e-12
A50: Form | B50: =RP_wood!G11 -> 2.0298831e-13 | C50: =RP_wood!J11 -> 2.0298831e-13 | D50: =RP_wood!M11 -> 2.0298831e-13 | E50: =RP_wood!P11 -> 2.0298831e-12 | H50: =RP_concrete!G13 -> 1.1388866e-12 | I50: =RP_concrete!J13 -> 1.0871191e-12 | M50: =RP_SICUT!G11 -> 2.6448778e-12
A51: Chemikalien | B51: =RP_wood!G12 -> 2.1389086e-12 | C51: =RP_wood!J12 -> 2.1389086e-12 | D51: =RP_wood!M12 -> 2.1389086e-12 | E51: =RP_wood!P12 -> 2.1389086e-12
A52: Elektrizität | B52: =RP_wood!G13 -> 3.4746135e-12 | C52: =RP_wood!J13 -> 3.5034228e-12 | D52: =RP_wood!M13 -> 3.0957622e-12 | E52: =RP_wood!P13 -> 1.7848695e-11 | H52: =RP_concrete!G14 -> 8.835725e-13 | I52: =RP_concrete!J14 -> 8.835725e-13 | M52: =RP_SICUT!G12 -> 2.4050663e-12 | N52: =RP_SICUT!J12 -> 2.4050663e-12 | O52: =RP_SICUT!M12 -> 1.6033776e-12 | P52: =RP_SICUT!P12 -> 1.2025332e-12 | Q52: =RP_SICUT!S12 -> 1.2025332e-12
A53: Wärme | B53: =RP_wood!G14 -> 1.2374461e-14 | C53: =RP_wood!J14 -> 1.2374461e-14 | D53: =RP_wood!M14 -> 3.15e-16 | E53: =RP_wood!P14 -> 1.5971434e-14 | H53: =RP_concrete!G15 -> 0 | I53: =RP_concrete!J15 -> 0 | M53: =RP_SICUT!G13 -> 1.5468077e-13 | N53: =RP_SICUT!J13 -> 1.5468077e-13 | O53: =RP_SICUT!M13 -> 1.0312051e-13 | P53: =RP_SICUT!P13 -> 7.7340384e-14 | Q53: =RP_SICUT!S13 -> 7.7340384e-14
A54: Landtransport | B54: =RP_wood!G15 -> 4.5695933e-14 | C54: =RP_wood!J15 -> 4.5695933e-14 | D54: =RP_wood!M15 -> 2.9289205e-14 | E54: =RP_wood!P15 -> 2.1225265e-12 | H54: =RP_concrete!G16 -> 2.4779963e-14 | I54: =RP_concrete!J16 -> 2.4779963e-14 | M54: =RP_SICUT!G14 -> 5.7119916e-14 | N54: =RP_SICUT!J14 -> 5.7119916e-14 | O54: =RP_SICUT!M14 -> 3.8079944e-14 | P54: =RP_SICUT!P14 -> 2.8559958e-14 | Q54: =RP_SICUT!S14 -> 2.8559958e-14
A55: Auslandtransport | B55: =RP_wood!G16 -> 0 | C55: =RP_wood!J16 -> 0 | D55: =RP_wood!M16 -> 0 | E55: =RP_wood!P16 -> 0 | H55: =RP_concrete!G17 -> 0 | I55: =RP_concrete!J17 -> 0 | M55: =RP_SICUT!G15 -> 0 | N55: =RP_SICUT!J15 -> 0 | O55: =RP_SICUT!M15 -> 0 | P55: =RP_SICUT!P15 -> 0 | Q55: =RP_SICUT!S15 -> 0
A56: ressource pressure | B56: =RP_wood!G17 -> 6.8592474e-12 | C56: =RP_wood!J17 -> 7.0933901e-12 | D56: =RP_wood!M17 -> 6.45193e-12 | E56: =RP_wood!P17 -> 2.5182651e-11 | H56: =RP_concrete!G18 -> 5.016169e-12 | I56: =RP_concrete!J18 -> 4.2055248e-12 | M56: =RP_SICUT!G16 -> 1.4475232e-11 | N56: =RP_SICUT!J16 -> 4.0982272e-12 | O56: =RP_SICUT!M16 -> 2.7321514e-12 | P56: =RP_SICUT!P16 -> 2.0491136e-12 | Q56: =RP_SICUT!S16 -> 7.2376158e-12
A63: Category explanation
B66: wood | C66: concrete | D66: SICUT
A67: bulk material 1 | B67: beech or oak | C67: cement | D67: PET
A68: bulk material 2 | B68: - | C68: gravel | D68: -
A69: reinforcement | B69: - | C69: reinforcing bars | D69: glass fibers
A70: form | B70: ribbed plate | C70: sleeper sole | D70: -
A71: chemicals | B71: creosote | C71: - | D71: -

Sheet Materials and energy
A1: Materials and energy
G3: Impact of increased secondary material use. | Q3: Impact of increased recycling and cascading.
G4: primary material content | I4: manufacturing losses | M4: electricity required [kWh/kg] | O4: heat required [kWh/kg] | Q4: EoL products
A5: Material characteristics | E5: per sleeper [kg] | G5: basic | H5: green | I5: uniformal | M5: uniformal | O5: uniformal | Q5: basic | R5: green | S5: basic | T5: green | U5: basic | V5: green
A6: material | B6: sleeper type | C6: ERP identifier | D6: use | E6: mass | F6: remarks | G6: basic_primary material content | H6: green_primary material content | I6: manufacturing losses | J6: collection rate | K6: recycling rate | L6: cascading rate | M6: electricity to manufacture product | N6: electricity to recycle/cascade product | O6: heat to manufacture product | P6: heat to recycle/cascade product | Q6: basic_collection rate | R6: green_collection rate | S6: basic_recycling rate | T6: green_recycling rate | U6: basic_cascading rate | V6: green_cascading rate
A7: cement unspecified | B7: concrete | C7: cement unspecified | D7: bulk material | E7: 170 | G7: 1 | H7: 1 | I7: 0.1 | J7: 1 | K7: 0 | L7: 0.9 | M7: 0.1 | N7: 0.1 | O7: 0 | P7: 0 | Q7: 1 | R7: 1 | S7: 0 | T7: 0 | U7: 0.5 | V7: 0.8
A8: water | B8: concrete | C8: water | D8: bulk material | E8: 20 | F8: neglected | G8: 0 | H8: 0 | I8: 0 | J8: 0 | K8: 0 | L8: 0 | M8: 0 | N8: 0 | O8: 0 | P8: 0 | Q8: 0 | R8: 0 | S8: 0 | T8: 0 | U8: 0 | V8: 0
A9: gravel | B9: concrete | C9: gravel | D9: bulk material | E9: 100 | G9: 1 | H9: 0.5 | I9: 0.1 | J9: 1 | K9: 0.9 | L9: 0 | M9: 0.1 | N9: 0.1 | O9: 0 | P9: 0 | Q9: 1 | R9: 1 | S9: 0.5 | T9: 0.8 | U9: 0.1 | V9: 0.15
A10: steel alloyed | B10: concrete | C10: steel alloyed | D10: reinforcement | E10: 0 | F10: combined with steel unalloyed; Vorspannlitzen, Befestigungen | G10: 0 | H10: 0 | I10: 0 | J10: 0 | K10: 0 | L10: 0 | M10: 0 | N10: 0 | O10: 0 | P10: 0 | Q10: 0 | R10: 0 | S10: 0 | T10: 0 | U10: 0 | V10: 0
A11: low-alloyed steel | B11: concrete | C11: low-alloyed steel | D11: reinforcement | E11: 20 | F11: Spanneisen | G11: 1 | H11: 0.5 | I11: 0.1 | J11: 1 | K11: 0.9 | L11: 0 | M11: 1 | N11: 2 | O11: 0 | P11: 0 | Q11: 1 | R11: 1 | S11: 0.7 | T11: 0.9 | U11: 0 | V11: 0
A12: PA-GF30 | B12: concrete | C12: PA-GF30 | D12: form | E12: 0.32 | F12: neglected | G12: 0 | H12: 0 | I12: 0 | J12: 0 | K12: 0 | L12: 0 | M12: 0 | N12: 0 | O12: 0 | P12: 0 | Q12: 0 | R12: 0 | S12: 0 | T12: 0 | U12: 0 | V12: 0
A13: PUR | B13: concrete | C13: PUR | D13: form | E13: 5 | F13: Besohlung; Bei Getzner als Sylomer®; beschrieben durch SLB 7000 FT | G13: 1 | H13: 1 | I13: 0.2 | J13: 1 | K13: 0 | L13: 0.5 | M13: 1 | N13: 1 | O13: 0 | P13: 0 | Q13: 1 | R13: 1 | S13: 0 | T13: 0 | U13: 0.1 | V13: 0.2
A14: concrete additives | B14: concrete | C14: concrete additives | D14: chemicals | E14: 0.5 | F14: neglected | G14: 0 | H14: 0 | I14: 0 | J14: 0 | K14: 0 | L14: 0 | M14: 0 | N14: 0 | O14: 0 | P14: 0 | Q14: 0 | R14: 0 | S14: 0 | T14: 0 | U14: 0 | V14: 0
A15: hardwood | B15: wood | C15: hardwood | D15: bulk material | E15: 70 | F15: Entweder Buche oder Eiche | G15: 1 | H15: 1 | I15: 0.1 | J15: 1 | K15: 0 | L15: 0.9 | M15: 0 | N15: 0.1 | O15: 0 | P15: 0 | Q15: 1 | R15: 1 | S15: 0 | T15: 0 | U15: 0 | V15: 0
A16: oak | B16: wood | C16: oak | D16: bulk material | E16: 70 | F16: Entweder Buche oder Eiche | G16: 1 | H16: 1 | I16: 0.1 | J16: 1 | K16: 0 | L16: 0.9 | M16: 0 | N16: 0.1 | O16: 0 | P16: 0 | Q16: 1 | R16: 1 | S16: 0 | T16: 0 | U16: 0 | V16: 0
A17: low-alloyed steel | B17: wood | C17: low-alloyed steel | D17: form | E17: 12 | F17: Rippenplatte, Befestigungen | G17: 1 | H17: 0.5 | I17: 0.1 | J17: 1 | K17: 0.9 | L17: 0 | M17: 1 | N17: 2 | O17: 0 | P17: 0 | Q17: 1 | R17: 1 | S17: 0.7 | T17: 0.9 | U17: 0 | V17: 0
A18: carbolineum | B18: wood | C18: carbolineum | D18: chemicals | E18: 12 | F18: Teeröl; ca.75-90 % Polycyclische aromatische Kohlenwasserstoffe und 5-17 % Xylenole und Naphthole und diverses | G18: 1 | H18: 1 | I18: 0.1 | J18: 1 | K18: 0 | L18: 0 | M18: 20 | N18: 0 | O18: 1 | P18: 0 | Q18: 0.5 | R18: 0.5 | S18: 0 | T18: 0 | U18: 0 | V18: 0
A19: PET | B19: SICUT | C19: PET | D19: bulk material | E19: 65 | F19: Recycleter PET | G19: 0 | H19: 0 | I19: 0.1 | J19: 1 | K19: 0.9 | L19: 0 | M19: 1 | N19: 1 | O19: 0 | P19: 0 | Q19: 1 | R19: 1 | S19: 0 | T19: 0.5 | U19: 0 | V19: 0.4
A20: glass fibre | B20: SICUT | C20: glass fibre | D20: bulk material | E20: 20 | F20: nicht subkutan brechend | G20: 1 | H20: 0.5 | I20: 0.1 | J20: 1 | K20: 0.9 | L20: 0 | M20: 1 | N20: 1 | O20: 3 | P20: 3 | Q20: 1 | R20: 1 | S20: 0 | T20: 0.5 | U20: 0 | V20: 0.4
A23: Sleeper characteristics | C23: [km]
A24: sleeper type | B24: lifetime [a] | C24: manufacturing transport | D24: installation transport | E24: disposal transport | F24: railway gravel thickness [m]
A25: concrete | B25: 40 | D25: 150 | F25: 0.35
A26: wood | B26: 25 | D26: 500 | F26: 0.25
A27: SICUT | B27: 20 | D27: 600
C30: electricity mix
A31: electricity source | B31: ERP identifier | C31: basic | D31: green
A32: electricity, coal | B32: el, coal | C32: 0 | D32: 0
A33: electricity, oil | B33: el, oil | C33: 0 | D33: 0
A34: electricity, gas | B34: el, gas | C34: 0.019 | D34: 0
A35: electricity, nuclear | B35: el, nuclear | C35: 0.289 | D35: 0
A36: electricity, wind, onshore | B36: el, wind, on | C36: 0.01 | D36: 0.1
A37: electricity, wind, offshore | B37: el, wind, off | C37: 0 | D37: 0
A38: electricity, geo | B38: el, geo | C38: 0 | D38: 0
A39: electricity, wood | B39: el, wood | C39: 0.02 | D39: =tbl_electricity[[#This Row],[basic]] -> 0.02
A40: electricity, hydro | B40: el, hydro | C40: =1-SUM(C32:C39,C41:C42) -> 0.6435 | D40: =1-SUM(D32:D39,D41:D42) -> 0.38
A41: electricity, PV, desert | B41: el, PV, desert | C41: 0 | D41: 0
A42: electricity, PV, roof | B42: el, PV, roof | C42: 0.0185 | D42: 0.5
C45: heat mix
A46: heat source | B46: ERP identifier | C46: basic | D46: green
A47: heat, gas | B47: ht, gas | C47: 0.5 | D47: 0
...

Sheet ERP
A1: Ecological Resource Potentials
A2: based on ecoinvent, ATP, Lenzen, IEA PVPS | C2: v3.9 cut-off
A4: Identifier | B4: Process/product | C4: Unit | D4: FU | E4: version | F4: category | G4: ERP effective [FU/a] | H4: limiting boundary
A5: el, coal | B5: electricity, coal | C5: kilowatt hour | D5: 1 | E5: ecoinvent3_9 | F5: electricity | G5: 7.5680604e+11 | H5: CO_2
A6: el, oil | B6: electricity, oil | C6: kilowatt hour | D6: 1 | E6: ecoinvent3_9 | F6: electricity | G6: 8.802081e+11 | H6: CO_2
A7: el, gas | B7: electricity, gas | C7: kilowatt hour | D7: 1 | E7: ecoinvent3_9 | F7: electricity | G7: 1.4210338e+12 | H7: CO_2
A8: el, nuclear | B8: electricity, nuclear | C8: kilowatt hour | D8: 1 | E8: ecoinvent3_9 | F8: electricity | G8: 7.0311942e+12 | H8: CO_2
A9: el, wind, on | B9: electricity, wind, onshore | C9: kilowatt hour | D9: 1 | E9: ecoinvent3_9 | F9: electricity | G9: 1130000000000 | H9: biophysical | K9: f
A10: el, wind, off | B10: electricity, wind, offshore | C10: kilowatt hour | D10: 1 | E10: ecoinvent3_9 | F10: electricity | G10: 984000000000 | H10: biophysical
A11: el, geo | B11: electricity, geothermal | C11: kilowatt hour | D11: 1 | E11: ecoinvent3_9 | F11: electricity | G11: 2548000000000 | H11: biophysical
A12: el, wood | B12: electricity, wood | C12: kilowatt hour | D12: 1 | E12: ecoinvent3_9 | F12: electricity | G12: 1120000000000 | H12: biophysical
A13: el, hydro | B13: electricity, hydro | C13: kilowatt hour | D13: 1 | E13: ecoinvent3_9 | F13: electricity | G13: 3669000000000 | H13: biophysical
A14: el, PV, desert | B14: electricity, solar, desert | C14: kilowatt hour | D14: 1 | E14: ecoinvent3_9 | F14: electricity | G14: 2.0237444e+13 | H14: CO_2
A15: el, PV, roof | B15: electricity, PV, rooftop | C15: kilowatt hour | D15: 1 | E15: ecoinvent3_9 | F15: electricity | G15: 2.8108667e+13 | H15: CO_2
A16: ht, gas | B16: heat, gas | C16: kWh | D16: 1 | E16: ecoinvent3_9 | F16: heat | G16: 6.0153881e+13 | H16: CO_2
A17: ht, oil | B17: heat, oil | C17: kWh | D17: 1 | E17: ecoinvent3_9 | F17: heat | G17: 3.3059022e+13 | H17: CO_2
A18: ht, propane | B18: heat, propane, industrial | C18: kWh | D18: 1 | E18: ecoinvent3_9 | F18: heat | G18: 3.5511569e+13 | H18: CO_2
A19: ht, wood | B19: heat, wood | C19: kWh | D19: 1 | E19: ecoinvent3_9 | F19: heat | G19: 4480000000000 | H19: biophysical
A20: ht, solar | B20: heat, solar | C20: kWh | D20: 1 | E20: ecoinvent3_9 | F20: heat | G20: 8.3809524e+14 | H20: biophysical
A21: trans, freight, train, diesel | B21: freight, train, diesel | C21: ton kilometer | D21: 1 | E21: ecoinvent3_9 | F21: transport | G21: 1.832508e+13 | H21: CO_2
... A61: Polylactic acid (PLA) | B61: polylactide, granulate//[GLO] market for polylactide, granulate | C61: kilogram | D61: 1 | E61: ecoinvent3_9 | F61: Material | G61: 1.8058516e+11 | H61: CO_2

Sheet RP_wood
A1: Resource Pressure Calculation
A3: wood | D3: option | F3: wo_01 | I3: wo_02 | L3: wo_03 | O3: wo_04 | R3: wo_05 | U3: wo_06
D4: description | F4: hardwood, basic | I4: hardwood, hohe Sägeverluste | L4: hardwood, green | O4: Charles idea
D5: primary material content | F5: basic_primary material content | I5: basic_primary material content | L5: green_primary material content
D6: collection rate of EoL sleeper materials | F6: basic_collection rate | I6: basic_collection rate | L6: green_collection rate
D7: recycling rate of collected EoL sleeper materials | F7: basic_recycling rate | I7: basic_recycling rate | L7: green_recycling rate
D8: cascading rate of collected EoL sleeper materials | F8: basic_cascading rate | I8: basic_cascading rate | L8: green_cascading rate
G9: τ | J9: τ | M9: τ | P9: τ | S9: τ | V9: τ
D10: bulk material | F10: hardwood | G10: =F45 -> 9.8466667e-13 | I10: hardwood | J10: =I45 -> 1.19e-12 | L10: hardwood | M10: =L45 -> 9.8466667e-13 | O10: hardwood | P10: =O45 -> 1.0266667e-12 | S10: =R45 -> #N/A | V10: =U45 -> #N/A
D11: form | F11: low-alloyed steel | G11: =F73 -> 2.0298831e-13 | I11: low-alloyed steel | J11: =I73 -> 2.0298831e-13 | L11: low-alloyed steel | M11: =L73 -> 2.0298831e-13 | O11: low-alloyed steel | P11: =O73 -> 2.0298831e-12 | S11: =R73 -> #N/A | V11: =U73 -> #N/A
D12: chemicals | F12: carbolineum | G12: =F101 -> 2.1389086e-12 | I12: carbolineum | J12: =I101 -> 2.1389086e-12 | L12: carbolineum | M12: =L101 -> 2.1389086e-12 | O12: carbolineum | P12: =O101 -> 2.1389086e-12 | S12: =R101 -> #N/A | V12: =U101 -> #N/A
D13: electricity | F13: basic | G13: =F122 -> 3.4746135e-12 | I13: basic | J13: =I122 -> 3.5034228e-12 | L13: green | M13: =L122 -> 3.0957622e-12 | O13: basic | P13: =O122 -> 1.7848695e-11 | S13: =R122 -> #N/A | V13: =U122 -> #N/A
D14: heat | F14: basic | G14: =F137 -> 1.2374461e-14 | I14: basic | J14: =I137 -> 1.2374461e-14 | L14: green | M14: =L137 -> 3.15e-16 | O14: basic | P14: =O137 -> 1.5971434e-14 | S14: =R137 -> #N/A | V14: =U137 -> #N/A
D15: transport land | F15: basic_land | G15: =F151 -> 4.5695933e-14 | I15: basic_land | J15: =I151 -> 4.5695933e-14 | L15: green_land | M15: =L151 -> 2.9289205e-14 | O15: basic_land | P15: =O151 -> 2.1225265e-12 | S15: =R151 -> #N/A | V15: =U151 -> #N/A
D16: transport overseas | F16: basic_overseas | G16: =F164 -> 0 | I16: basic_overseas | J16: =I164 -> 0 | L16: green_overseas | M16: =L164 -> 0 | O16: basic_overseas | P16: =O164 -> 0 | S16: =R164 -> #N/A | V16: =U164 -> #N/A
D17: ressource pressure | G17: =SUM(G10:G16) -> 6.8592474e-12 | J17: =SUM(J10:J16) -> 7.0933901e-12 | M17: =SUM(M10:M16) -> 6.45193e-12 | P17: =SUM(P10:P16) -> 2.5182651e-11 | S17: =SUM(S10:S16) -> #N/A | V17: =SUM(V10:V16) -> #N/A
B18: Input cell
A19: aspect | B19: icon | C19: name | D19: description | E19: unit
A20: bulk material | B20: mat | C20: material | D20: ERP identifier | F20: =INDEX(tbl_material[],MATCH(F$10,tbl_material[ERP identifier],0),MATCH(RP_wood!$D$20,tbl_material[#Headers],0)) -> hardwood | I20: =INDEX(tbl_material[],MATCH(I$10,tbl_material[ERP identifier],0),MATCH(RP_wood!$D$20,tbl_material[#Headers],0)) -> hardwood | L20: =INDEX(tbl_material[],MATCH(L$10,tbl_material[ERP identifier],0),MATCH(RP_wood!$D$20,tbl_material[#Headers],0)) -> hardwood | O20: =INDEX(tbl_material[],MATCH(O$10,tbl_material[ERP identifier],0),MATCH(RP_wood!$D$20,tbl_material[#Headers],0)) -> hardwood | R20: =INDEX(tbl_material[],MATCH(R$10,tbl_material[ERP identifier],0),MATCH(RP_wood!$D$20,tbl_material[#Headers],0)) -> #N/A | U20: =INDEX(tbl_material[],MATCH(U$10,tbl_material[ERP identifier],0),MATCH(RP_wood!$D$20,tbl_material[#Headers],0)) -> #N/A
B21: ERP | C21: Environmental Ressource Potential | D21: ERP effective [FU/a] | E21: kg/a | F21: =INDEX(tbl_ERP[],MATCH(F20,tbl_ERP[Identifier],0),MATCH(RP_wood!$D$21,tbl_ERP[#Headers],0)) -> 3000000000000 | I21: =INDEX(tbl_ERP[],MATCH(I20,tbl_ERP[Identifier],0),MATCH(RP_wood!$D$21,tbl_ERP[#Headers],0)) -> 3000000000000 | L21: =INDEX(tbl_ERP[],MATCH(L20,tbl_ERP[Identifier],0),MATCH(RP_wood!$D$21,tbl_ERP[#Headers],0)) -> 3000000000000 | O21: =INDEX(tbl_ERP[],MATCH(O20,tbl_ERP[Identifier],0),MATCH(RP_wood!$D$21,tbl_ERP[#Headers],0)) -> 3000000000000 | R21: =INDEX(tbl_ERP[],MATCH(R20,tbl_ERP[Identifier],0),MATCH(RP_wood!$D$21,tbl_ERP[#Headers],0)) -> #N/A | U21: =INDEX(tbl_ERP[],MATCH(U20,tbl_ERP[Identifier],0),MATCH(RP_wood!$D$21,tbl_ERP[#Headers],0)) -> #N/A
C23: primary material content | D23: per input (primary and secondary) without recycling | E23: - | F23: =INDEX(tbl_material[],MATCH(F$10,tbl_material[material],0),MATCH(RP_wood!$F$5,tbl_material[#Headers],0)) -> 1 | I23: =INDEX(tbl_material[],MATCH(I$10,tbl_material[material],0),MATCH(RP_wood!$F$5,tbl_material[#Headers],0)) -> 1 | L23: =INDEX(tbl_material[],MATCH(L$10,tbl_material[material],0),MATCH(RP_wood!$F$5,tbl_material[#Headers],0)) -> 1 | O23: =INDEX(tbl_material[],MATCH(O$10,tbl_material[material],0),MATCH(RP_wood!$F$5,tbl_material[#Headers],0)) -> 1 | R23: =INDEX(tbl_material[],MATCH(R$10,tbl_material[material],0),MATCH(RP_wood!$F$5,tbl_material[#Headers],0)) -> #N/A | U23: =INDEX(tbl_material[],MATCH(U$10,tbl_material[material],0),MATCH(RP_wood!$F$5,tbl_material[#Headers],0)) -> #N/A
C24: secondary material content | D24: per input (primary and secondary) without recycling | E24: - | F24: =1-F23 -> 0 | I24: =1-I23 -> 0 | L24: =1-L23 -> 0 | O24: =1-O23 -> 0 | R24: =1-R23 -> #N/A | U24: =1-U23 -> #N/A
C26: mass | D26: per sleeper | E26: kg | F26: =INDEX(tbl_material[],MATCH(F$10,tbl_material[material],0),MATCH(RP_wood!$C$26,tbl_material[#Headers],0)) -> 70 | I26: =INDEX(tbl_material[],MATCH(I$10,tbl_material[material],0),MATCH(RP_wood!$C$26,tbl_material[#Headers],0)) -> 70 | L26: =INDEX(tbl_material[],MATCH(L$10,tbl_material[material],0),MATCH(RP_wood!$C$26,tbl_material[#Headers],0)) -> 70 | O26: =INDEX(tbl_material[],MATCH(O$10,tbl_material[material],0),MATCH(RP_wood!$C$26,tbl_material[#Headers],0)) -> 70 | R26: =INDEX(tbl_material[],MATCH(R$10,tbl_material[material],0),MATCH(RP_wood!$C$26,tbl_material[#Headers],0)) -> #N/A | U26: =INDEX(tbl_material[],MATCH(U$10,tbl_material[material],0),MATCH(RP_wood!$C$26,tbl_material[#Headers],0)) -> #N/A
C27: manufacturing losses | D27: in relation to product | E27: - | F27: =INDEX(tbl_material[],MATCH(F$10,tbl_material[material],0),MATCH(RP_wood!$C$27,tbl_material[#Headers],0)) -> 0.1 | I27: 0.5 | L27: =INDEX(tbl_material[],MATCH(L$10,tbl_material[material],0),MATCH(RP_wood!$C$27,tbl_material[#Headers],0)) -> 0.1 | O27: 0.1 | R27: =INDEX(tbl_material[],MATCH(R$10,tbl_material[material],0),MATCH(RP_wood!$C$27,tbl_material[#Headers],0)) -> #N/A | U27: =INDEX(tbl_material[],MATCH(U$10,tbl_material[material],0),MATCH(RP_wood!$C$27,tbl_material[#Headers],0)) -> #N/A
C28: manufacturing losses | D28: per product | E28: kg | F28: =F26*F27 -> 7 | I28: =I26*I27 -> 35 | L28: =L26*L27 -> 7 | O28: =O26*O27 -> 7 | R28: =R26*R27 -> #N/A | U28: =U26*U27 -> #N/A
C29: mass required | D29: per product | E29: kg | F29: =F26*(1+F27) -> 77 | I29: =I26*(1+I27) -> 105 | L29: =L26*(1+L27) -> 77 | O29: =O26*(1+O27) -> 77 | R29: =R26*(1+R27) -> #N/A | U29: =U26*(1+U27) -> #N/A
C31: collection rate | D31: of manufacturing losses | E31: - | F31: =INDEX(tbl_material[],MATCH(F$10,tbl_material[material],0),MATCH(RP_wood!$C$31,tbl_material[#Headers],0)) -> 1 | I31: =INDEX(tbl_material[],MATCH(I$10,tbl_material[material],0),MATCH(RP_wood!$C$31,tbl_material[#Headers],0)) -> 1 | L31: =INDEX(tbl_material[],MATCH(L$10,tbl_material[material],0),MATCH(RP_wood!$C$31,tbl_material[#Headers],0)) -> 1 | O31: =INDEX(tbl_material[],MATCH(O$10,tbl_material[material],0),MATCH(RP_wood!$C$31,tbl_material[#Headers],0)) -> 1 | R31: =INDEX(tbl_material[],MATCH(R$10,tbl_material[material],0),MATCH(RP_wood!$C$31,tbl_material[#Headers],0)) -> #N/A | U31: =INDEX(tbl_material[],MATCH(U$10,tbl_material[material],0),MATCH(RP_wood!$C$31,tbl_material[#Headers],0)) -> #N/A
C32: recycling rate | D32: of collected manufacturing losses | E32: - | F32: =INDEX(tbl_material[],MATCH(F$10,tbl_material[material],0),MATCH(RP_wood!$C$32,tbl_material[#Headers],0)) -> 0 | I32: =INDEX(tbl_material[],MATCH(I$10,tbl_material[material],0),MATCH(RP_wood!$C$32,tbl_material[#Headers],0)) -> 0 | L32: =INDEX(tbl_material[],MATCH(L$10,tbl_material[material],0),MATCH(RP_wood!$C$32,tbl_material[#Headers],0)) -> 0 | O32: =INDEX(tbl_material[],MATCH(O$10,tbl_material[material],0),MATCH(RP_wood!$C$32,tbl_material[#Headers],0)) -> 0 | R32: =INDEX(tbl_material[],MATCH(R$10,tbl_material[material],0),MATCH(RP_wood!$C$32,tbl_material[#Headers],0)) -> #N/A | U32: =INDEX(tbl_material[],MATCH(U$10,tbl_material[material],0),MATCH(RP_wood!$C$32,tbl_material[#Headers],0)) -> #N/A
C33: cascading rate | D33: of collected manufacturing losses | E33: - | F33: =INDEX(tbl_material[],MATCH(F$10,tbl_material[material],0),MATCH(RP_wood!$C$33,tbl_material[#Headers],0)) -> 0.9 | I33: =INDEX(tbl_material[],MATCH(I$10,tbl_material[material],0),MATCH(RP_wood!$C$33,tbl_material[#Headers],0)) -> 0.9 | L33: =INDEX(tbl_material[],MATCH(L$10,tbl_material[material],0),MATCH(RP_wood!$C$33,tbl_material[#Headers],0)) -> 0.9 | O33: 0 | R33: =INDEX(tbl_material[],MATCH(R$10,tbl_material[material],0),MATCH(RP_wood!$C$33,tbl_material[#Headers],0)) -> #N/A | U33: =INDEX(tbl_material[],MATCH(U$10,tbl_material[material],0),MATCH(RP_wood!$C$33,tbl_material[#Headers],0)) -> #N/A
C34: loss rate | D34: of collected manufacturing losses | E34: - | F34: =1-F31+F31*(1-F32-F33) -> 0.1 | I34: =1-I31+I31*(1-I32-I33) -> 0.1 | L34: =1-L31+L31*(1-L32-L33) -> 0.1 | O34: =1-O31+O31*(1-O32-O33) -> 1 | R34: =1-R31+R31*(1-R32-R33) -> #N/A | U34: =1-U31+U31*(1-U32-U33) -> #N/A
C36: collection rate | D36: of EoL products | E36: - | F36: =INDEX(tbl_material[],MATCH(F$10,tbl_material[material],0),MATCH(RP_wood!$F$6,tbl_material[#Headers],0)) -> 1 | I36: =INDEX(tbl_material[],MATCH(I$10,tbl_material[material],0),MATCH(RP_wood!$I$6,tbl_material[#Headers],0)) -> 1 | L36: =INDEX(tbl_material[],MATCH(L$10,tbl_material[material],0),MATCH(RP_wood!$I$6,tbl_material[#Headers],0)) -> 1 | O36: =INDEX(tbl_material[],MATCH(O$10,tbl_material[material],0),MATCH(RP_wood!$I$6,tbl_material[#Headers],0)) -> 1 | R36: =INDEX(tbl_material[],MATCH(R$10,tbl_material[material],0),MATCH(RP_wood!$I$6,tbl_material[#Headers],0)) -> #N/A | U36: =INDEX(tbl_material[],MATCH(U$10,tbl_material[material],0),MATCH(RP_wood!$I$6,tbl_material[#Headers],0)) -> #N/A
C37: recycling rate | D37: of collected EoL products (base material) | E37: - | F37: =INDEX(tbl_material[],MATCH(F$10,tbl_material[material],0),MATCH(RP_wood!$F$7,tbl_material[#Headers],0)) -> 0 | I37: =INDEX(tbl_material[],MATCH(I$10,tbl_material[material],0),MATCH(RP_wood!$F$7,tbl_material[#Headers],0)) -> 0 | L37: =INDEX(tbl_material[],MATCH(L$10,tbl_material[material],0),MATCH(RP_wood!$F$7,tbl_material[#Headers],0)) -> 0 | O37: =INDEX(tbl_material[],MATCH(O$10,tbl_material[material],0),MATCH(RP_wood!$F$7,tbl_material[#Headers],0)) -> 0 | R37: =INDEX(tbl_material[],MATCH(R$10,tbl_material[material],0),MATCH(RP_wood!$F$7,tbl_material[#Headers],0)) -> #N/A | U37: =INDEX(tbl_material[],MATCH(U$10,tbl_material[material],0),MATCH(RP_wood!$F$7,tbl_material[#Headers],0)) -> #N/A
C38: cascading rate | D38: of collected EoL products (base material) | E38: - | F38: =INDEX(tbl_material[],MATCH(F$10,tbl_material[material],0),MATCH(RP_wood!$F$8,tbl_material[#Headers],0)) -> 0 | I38: =INDEX(tbl_material[],MATCH(I$10,tbl_material[material],0),MATCH(RP_wood!$F$8,tbl_material[#Headers],0)) -> 0 | L38: =INDEX(tbl_material[],MATCH(L$10,tbl_material[material],0),MATCH(RP_wood!$F$8,tbl_material[#Headers],0)) -> 0 | O38: =INDEX(tbl_material[],MATCH(O$10,tbl_material[material],0),MATCH(RP_wood!$F$8,tbl_material[#Headers],0)) -> 0 | R38: =INDEX(tbl_material[],MATCH(R$10,tbl_material[material],0),MATCH(RP_wood!$F$8,tbl_material[#Headers],0)) -> #N/A | U38: =INDEX(tbl_material[],MATCH(U$10,tbl_material[material],0),MATCH(RP_wood!$F$8,tbl_material[#Headers],0)) -> #N/A
C39: loss rate | D39: of collected EoL products (base material) | E39: - | F39: =1-F36+F36*(1-F37-F38) -> 1 | I39: =1-I36+I36*(1-I37-I38) -> 1 | L39: =1-L36+L36*(1-L37-L38) -> 1 | O39: =1-O36+O36*(1-O37-O38) -> 1 | R39: =1-R36+R36*(1-R37-R38) -> #N/A | U39: =1-U36+U36*(1-U37-U38) -> #N/A
C41: recyclability | D41: overall | E41: - | F41: =(F31*F32*F27+F36*F37)/(1+F27) -> 0 | I41: =(I31*I32*I27+I36*I37)/(1+I27) -> 0 | L41: =(L31*L32*L27+L36*L37)/(1+L27) -> 0 | O41: =(O31*O32*O27+O36*O37)/(1+O27) -> 0 | R41: =(R31*R32*R27+R36*R37)/(1+R27) -> #N/A | U41: =(U31*U32*U27+U36*U37)/(1+U27) -> #N/A
C42: cascadability | D42: overall | E42: - | F42: =(F31*F33*F27+F36*F38)/(1+F27) -> 0.081818182 | I42: =(I31*I33*I27+I36*I38)/(1+I27) -> 0.3 | L42: =(L31*L33*L27+L36*L38)/(1+L27) -> 0.081818182 | O42: =(O31*O33*O27+O36*O38)/(1+O27) -> 0 | R42: =(R31*R33*R27+R36*R38)/(1+R27) -> #N/A | U42: =(U31*U33*U27+U36*U38)/(1+U27) -> #N/A
C43: final loss | D43: overall | E43: - | F43: =1-F41-F42 -> 0.91818182 | I43: =1-I41-I42 -> 0.7 | L43: =1-L41-L42 -> 0.91818182 | O43: =1-O41-O42 -> 1 | R43: =1-R41-R42 -> #N/A | U43: =1-U41-U42 -> #N/A
B45: τ | C45: ressource pressure | D45: base material | E45: - | F45: =(0.5*F26/F21)*(1+F27)*(1/lifetime_wood)*(1+F23*(1-F41)-F41-F42) -> 9.8466667e-13 | I45: =(0.5*I26/I21)*(1+I27)*(1/lifetime_wood)*(1+I23*(1-I41)-I41-I42) -> 1.19e-12 | L45: =(0.5*L26/L21)*(1+L27)*(1/lifetime_wood)*(1+L23*(1-L41)-L41-L42) -> 9.8466667e-13 | O45: =(0.5*O26/O21)*(1+O27)*(1/lifetime_wood)*(1+O23*(1-O41)-O41-O42) -> 1.0266667e-12 | R45: =(0.5*R26/R21)*(1+R27)*(1/lifetime_wood)*(1+R23*(1-R41)-R41-R42) -> #N/A | U45: =(0.5*U26/U21)*(1+U27)*(1/lifetime_wood)*(1+U23*(1-U41)-U41-U42) -> #N/A
A48: form | B48: mat | C48: material | D48: ERP identifier | F48: =INDEX(tbl_material[],MATCH(F$11,tbl_material[ERP identifier],0),MATCH(RP_wood!$D$48,tbl_material[#Headers],0)) -> low-alloyed steel | I48: =INDEX(tbl_material[],MATCH(I$11,tbl_material[ERP identifier],0),MATCH(RP_wood!$D$48,tbl_material[#Headers],0)) -> low-alloyed steel | L48: =INDEX(tbl_material[],MATCH(L$11,tbl_material[ERP identifier],0),MATCH(RP_wood!$D$48,tbl_material[#Headers],0)) -> low-alloyed steel | O48: =INDEX(tbl_material[],MATCH(O$11,tbl_material[ERP identifier],0),MATCH(RP_wood!$D$48,tbl_material[#Headers],0)) -> low-alloyed steel | R48: =INDEX(tbl_material[],MATCH(R$11,tbl_material[ERP identifier],0),MATCH(RP_wood!$D$48,tbl_material[#Headers],0)) -> #N/A | U48: =INDEX(tbl_material[],MATCH(U$11,tbl_material[ERP identifier],0),MATCH(RP_wood!$D$48,tbl_material[#Headers],0)) -> #N/A
B49: ERP | C49: Environmental Ressource Potential | D49: ERP effective [FU/a] | E49: kg/a | F49: =INDEX(tbl_ERP[],MATCH(F48,tbl_ERP[Identifier],0),MATCH(RP_wood!$D$49,tbl_ERP[#Headers],0)) -> 4.3352251e+11 | I49: =INDEX(tbl_ERP[],MATCH(I48,tbl_ERP[Identifier],0),MATCH(RP_wood!$D$49,tbl_ERP[#Headers],0)) -> 4.3352251e+11 | L49: =INDEX(tbl_ERP[],MATCH(L48,tbl_ERP[Identifier],0),MATCH(RP_wood!$D$49,tbl_ERP[#Headers],0)) -> 4.3352251e+11 | O49: =INDEX(tbl_ERP[],MATCH(O48,tbl_ERP[Identifier],0),MATCH(RP_wood!$D$49,tbl_ERP[#Headers],0)) -> 4.3352251e+11 | R49: =INDEX(tbl_ERP[],MATCH(R48,tbl_ERP[Identifier],0),MATCH(RP_wood!$D$49,tbl_ERP[#Headers],0)) -> #N/A | U49: =INDEX(tbl_ERP[],MATCH(U48,tbl_ERP[Identifier],0),MATCH(RP_wood!$D$49,tbl_ERP[#Headers],0)) -> #N/A
...

Sheet RP_concrete
A1: Resource Pressure Calculation
A3: concrete | D3: option | F3: co_01 | I3: co_02 | L3: co_03 | O3: co_04 | R3: co_05
D4: description | F4: concrete basic 40 Jahre | I4: concrete green 40 Jahre
D5: primary material content | F5: basic_primary material content | I5: green_primary material content
D6: collection rate of EoL sleeper materials | F6: basic_collection rate | I6: green_collection rate
D7: recycling rate of collected EoL sleeper materials | F7: basic_recycling rate | I7: green_recycling rate
D8: cascading rate of collected EoL sleeper materials | F8: basic_cascading rate | I8: green_cascading rate
G9: τ | J9: τ | M9: τ | P9: τ | S9: τ
D10: bulk material 1 | F10: cement unspecified | G10: =F46 -> 2.5957925e-12 | I10: cement unspecified | J10: =I46 -> 2.1121044e-12 | M10: =L46 -> #N/A | P10: =O46 -> #N/A | S10: =R46 -> #N/A
D11: bulk material 2 | F11: gravel | G11: =F74 -> 1.5601221e-14 | I11: gravel | J11: =I74 -> 2.7980451e-15 | M11: =L74 -> #N/A | P11: =O74 -> #N/A | S11: =R74 -> #N/A
D12: reinforcement | F12: low-alloyed steel | G12: =F102 -> 3.5753622e-13 | I12: low-alloyed steel | J12: =I102 -> 9.5150769e-14 | M12: =L102 -> #N/A | P12: =O102 -> #N/A | S12: =R102 -> #N/A
D13: form | F13: PUR | G13: =F130 -> 1.1388866e-12 | I13: PUR | J13: =I130 -> 1.0871191e-12 | M13: =L130 -> #N/A | P13: =O130 -> #N/A | S13: =R130 -> #N/A
D14: electricity | F14: basic | G14: =F151 -> 8.835725e-13 | I14: basic | J14: =I151 -> 8.835725e-13 | M14: =L151 -> #N/A | P14: =O151 -> #N/A | S14: =R151 -> #N/A
D15: heat | F15: basic | G15: =F166 -> 0 | I15: basic | J15: =I166 -> 0 | M15: =L166 -> #N/A | P15: =O166 -> #N/A | S15: =R166 -> #N/A
D16: transport land | F16: basic_land | G16: =F180 -> 2.4779963e-14 | I16: basic_land | J16: =I180 -> 2.4779963e-14 | M16: =L180 -> #N/A | P16: =O180 -> #N/A | S16: =R180 -> #N/A
D17: transport overseas | F17: basic_overseas | G17: =F193 -> 0 | I17: basic_overseas | J17: =I193 -> 0 | M17: =L193 -> #N/A | P17: =O193 -> #N/A | S17: =R193 -> #N/A
D18: ressource pressure | G18: =SUM(G10:G17) -> 5.016169e-12 | J18: =SUM(J10:J17) -> 4.2055248e-12 | M18: =SUM(M10:M17) -> #N/A | P18: =SUM(P10:P17) -> #N/A | S18: =SUM(S10:S17) -> #N/A
B19: Input cell
A20: aspect | B20: icon | C20: name | D20: description | E20: unit
A21: bulk material 1 | B21: mat | C21: material | D21: ERP identifier | F21: =INDEX(tbl_material[],MATCH(F$10,tbl_material[ERP identifier],0),MATCH(RP_concrete!$D$21,tbl_material[#Headers],0)) -> cement unspecified | I21: =INDEX(tbl_material[],MATCH(I$10,tbl_material[ERP identifier],0),MATCH(RP_concrete!$D$21,tbl_material[#Headers],0)) -> cement unspecified | L21: =INDEX(tbl_material[],MATCH(L$10,tbl_material[ERP identifier],0),MATCH(RP_concrete!$D$21,tbl_material[#Headers],0)) -> #N/A | O21: =INDEX(tbl_material[],MATCH(O$10,tbl_material[ERP identifier],0),MATCH(RP_concrete!$D$21,tbl_material[#Headers],0)) -> #N/A | R21: =INDEX(tbl_material[],MATCH(R$10,tbl_material[ERP identifier],0),MATCH(RP_concrete!$D$21,tbl_material[#Headers],0)) -> #N/A
B22: ERP | C22: Environmental Ressource Potential | D22: ERP effective [FU/a] | E22: kg/a | F22: =INDEX(tbl_ERP[],MATCH(F21,tbl_ERP[Identifier],0),MATCH(RP_concrete!$D$22,tbl_ERP[#Headers],0)) -> 1.3179983e+12 | I22: =INDEX(tbl_ERP[],MATCH(I21,tbl_ERP[Identifier],0),MATCH(RP_concrete!$D$22,tbl_ERP[#Headers],0)) -> 1.3179983e+12 | L22: =INDEX(tbl_ERP[],MATCH(L21,tbl_ERP[Identifier],0),MATCH(RP_concrete!$D$22,tbl_ERP[#Headers],0)) -> #N/A | O22: =INDEX(tbl_ERP[],MATCH(O21,tbl_ERP[Identifier],0),MATCH(RP_concrete!$D$22,tbl_ERP[#Headers],0)) -> #N/A | R22: =INDEX(tbl_ERP[],MATCH(R21,tbl_ERP[Identifier],0),MATCH(RP_concrete!$D$22,tbl_ERP[#Headers],0)) -> #N/A
C24: primary material content | D24: per input (primary and secondary) without recycling | E24: - | F24: =INDEX(tbl_material[],MATCH(F$10,tbl_material[material],0),MATCH(RP_concrete!$F$5,tbl_material[#Headers],0)) -> 1 | I24: =INDEX(tbl_material[],MATCH(I$10,tbl_material[material],0),MATCH(RP_concrete!$I$5,tbl_material[#Headers],0)) -> 1 | L24: =INDEX(tbl_material[],MATCH(L$10,tbl_material[material],0),MATCH(RP_concrete!$I$5,tbl_material[#Headers],0)) -> #N/A | O24: =INDEX(tbl_material[],MATCH(O$10,tbl_material[material],0),MATCH(RP_concrete!$I$5,tbl_material[#Headers],0)) -> #N/A | R24: =INDEX(tbl_material[],MATCH(R$10,tbl_material[material],0),MATCH(RP_concrete!$I$5,tbl_material[#Headers],0)) -> #N/A
C25: secondary material content | D25: per input (primary and secondary) without recycling | E25: - | F25: =1-F24 -> 0 | I25: =1-I24 -> 0 | L25: =1-L24 -> #N/A | O25: =1-O24 -> #N/A | R25: =1-R24 -> #N/A
C27: mass | D27: per sleeper | E27: kg | F27: =INDEX(tbl_material[],MATCH(F$10,tbl_material[material],0),MATCH(RP_concrete!$C$27,tbl_material[#Headers],0)) -> 170 | I27: =INDEX(tbl_material[],MATCH(I$10,tbl_material[material],0),MATCH(RP_concrete!$C$27,tbl_material[#Headers],0)) -> 170 | L27: =INDEX(tbl_material[],MATCH(L$10,tbl_material[material],0),MATCH(RP_concrete!$C$27,tbl_material[#Headers],0)) -> #N/A | O27: =INDEX(tbl_material[],MATCH(O$10,tbl_material[material],0),MATCH(RP_concrete!$C$27,tbl_material[#Headers],0)) -> #N/A | R27: =INDEX(tbl_material[],MATCH(R$10,tbl_material[material],0),MATCH(RP_concrete!$C$27,tbl_material[#Headers],0)) -> #N/A
C28: manufacturing losses | D28: in relation to product | E28: - | F28: =INDEX(tbl_material[],MATCH(F$10,tbl_material[material],0),MATCH(RP_concrete!$C$28,tbl_material[#Headers],0)) -> 0.1 | I28: =INDEX(tbl_material[],MATCH(I$10,tbl_material[material],0),MATCH(RP_concrete!$C$28,tbl_material[#Headers],0)) -> 0.1 | L28: =INDEX(tbl_material[],MATCH(L$10,tbl_material[material],0),MATCH(RP_concrete!$C$28,tbl_material[#Headers],0)) -> #N/A | O28: =INDEX(tbl_material[],MATCH(O$10,tbl_material[material],0),MATCH(RP_concrete!$C$28,tbl_material[#Headers],0)) -> #N/A | R28: =INDEX(tbl_material[],MATCH(R$10,tbl_material[material],0),MATCH(RP_concrete!$C$28,tbl_material[#Headers],0)) -> #N/A
C29: manufacturing losses | D29: per product | E29: kg | F29: =F27*F28 -> 17 | I29: =I27*I28 -> 17 | L29: =L27*L28 -> #N/A | O29: =O27*O28 -> #N/A | R29: =R27*R28 -> #N/A
C30: mass required | D30: per product | E30: kg | F30: =F27*(1+F28) -> 187 | I30: =I27*(1+I28) -> 187 | L30: =L27*(1+L28) -> #N/A | O30: =O27*(1+O28) -> #N/A | R30: =R27*(1+R28) -> #N/A
C32: collection rate | D32: of manufacturing losses | E32: - | F32: =INDEX(tbl_material[],MATCH(F$10,tbl_material[material],0),MATCH(RP_concrete!$C$32,tbl_material[#Headers],0)) -> 1 | I32: =INDEX(tbl_material[],MATCH(I$10,tbl_material[material],0),MATCH(RP_concrete!$C$32,tbl_material[#Headers],0)) -> 1 | L32: =INDEX(tbl_material[],MATCH(L$10,tbl_material[material],0),MATCH(RP_concrete!$C$32,tbl_material[#Headers],0)) -> #N/A | O32: =INDEX(tbl_material[],MATCH(O$10,tbl_material[material],0),MATCH(RP_concrete!$C$32,tbl_material[#Headers],0)) -> #N/A | R32: =INDEX(tbl_material[],MATCH(R$10,tbl_material[material],0),MATCH(RP_concrete!$C$32,tbl_material[#Headers],0)) -> #N/A
C33: recycling rate | D33: of collected manufacturing losses | E33: - | F33: =INDEX(tbl_material[],MATCH(F$10,tbl_material[material],0),MATCH(RP_concrete!$C$33,tbl_material[#Headers],0)) -> 0 | I33: =INDEX(tbl_material[],MATCH(I$10,tbl_material[material],0),MATCH(RP_concrete!$C$33,tbl_material[#Headers],0)) -> 0 | L33: =INDEX(tbl_material[],MATCH(L$10,tbl_material[material],0),MATCH(RP_concrete!$C$33,tbl_material[#Headers],0)) -> #N/A | O33: =INDEX(tbl_material[],MATCH(O$10,tbl_material[material],0),MATCH(RP_concrete!$C$33,tbl_material[#Headers],0)) -> #N/A | R33: =INDEX(tbl_material[],MATCH(R$10,tbl_material[material],0),MATCH(RP_concrete!$C$33,tbl_material[#Headers],0)) -> #N/A
C34: cascading rate | D34: of collected manufacturing losses | E34: - | F34: =INDEX(tbl_material[],MATCH(F$10,tbl_material[material],0),MATCH(RP_concrete!$C$34,tbl_material[#Headers],0)) -> 0.9 | I34: =INDEX(tbl_material[],MATCH(I$10,tbl_material[material],0),MATCH(RP_concrete!$C$34,tbl_material[#Headers],0)) -> 0.9 | L34: =INDEX(tbl_material[],MATCH(L$10,tbl_material[material],0),MATCH(RP_concrete!$C$34,tbl_material[#Headers],0)) -> #N/A | O34: =INDEX(tbl_material[],MATCH(O$10,tbl_material[material],0),MATCH(RP_concrete!$C$34,tbl_material[#Headers],0)) -> #N/A | R34: =INDEX(tbl_material[],MATCH(R$10,tbl_material[material],0),MATCH(RP_concrete!$C$34,tbl_material[#Headers],0)) -> #N/A
C35: loss rate | D35: of collected manufacturing losses | E35: - | F35: =1-F32+F32*(1-F33-F34) -> 0.1 | I35: =1-I32+I32*(1-I33-I34) -> 0.1 | L35: =1-L32+L32*(1-L33-L34) -> #N/A | O35: =1-O32+O32*(1-O33-O34) -> #N/A | R35: =1-R32+R32*(1-R33-R34) -> #N/A
C37: collection rate | D37: of EoL products | E37: - | F37: =INDEX(tbl_material[],MATCH(F$10,tbl_material[material],0),MATCH(RP_concrete!$F$6,tbl_material[#Headers],0)) -> 1 | I37: =INDEX(tbl_material[],MATCH(I$10,tbl_material[material],0),MATCH(RP_concrete!$I$6,tbl_material[#Headers],0)) -> 1 | L37: =INDEX(tbl_material[],MATCH(L$10,tbl_material[material],0),MATCH(RP_concrete!$I$6,tbl_material[#Headers],0)) -> #N/A | O37: =INDEX(tbl_material[],MATCH(O$10,tbl_material[material],0),MATCH(RP_concrete!$I$6,tbl_material[#Headers],0)) -> #N/A | R37: =INDEX(tbl_material[],MATCH(R$10,tbl_material[material],0),MATCH(RP_concrete!$I$6,tbl_material[#Headers],0)) -> #N/A
C38: recycling rate | D38: of collected EoL products (base material) | E38: - | F38: =INDEX(tbl_material[],MATCH(F$10,tbl_material[material],0),MATCH(RP_concrete!$F$7,tbl_material[#Headers],0)) -> 0 | I38: =INDEX(tbl_material[],MATCH(I$10,tbl_material[material],0),MATCH(RP_concrete!$I$7,tbl_material[#Headers],0)) -> 0 | L38: =INDEX(tbl_material[],MATCH(L$10,tbl_material[material],0),MATCH(RP_concrete!$I$7,tbl_material[#Headers],0)) -> #N/A | O38: =INDEX(tbl_material[],MATCH(O$10,tbl_material[material],0),MATCH(RP_concrete!$I$7,tbl_material[#Headers],0)) -> #N/A | R38: =INDEX(tbl_material[],MATCH(R$10,tbl_material[material],0),MATCH(RP_concrete!$I$7,tbl_material[#Headers],0)) -> #N/A
C39: cascading rate | D39: of collected EoL products (base material) | E39: - | F39: =INDEX(tbl_material[],MATCH(F$10,tbl_material[material],0),MATCH(RP_concrete!$F$8,tbl_material[#Headers],0)) -> 0.5 | I39: =INDEX(tbl_material[],MATCH(I$10,tbl_material[material],0),MATCH(RP_concrete!$I$8,tbl_material[#Headers],0)) -> 0.8 | L39: =INDEX(tbl_material[],MATCH(L$10,tbl_material[material],0),MATCH(RP_concrete!$I$8,tbl_material[#Headers],0)) -> #N/A | O39: =INDEX(tbl_material[],MATCH(O$10,tbl_material[material],0),MATCH(RP_concrete!$I$8,tbl_material[#Headers],0)) -> #N/A | R39: =INDEX(tbl_material[],MATCH(R$10,tbl_material[material],0),MATCH(RP_concrete!$I$8,tbl_material[#Headers],0)) -> #N/A
C40: loss rate | D40: of collected EoL products (base material) | E40: - | F40: =1-F37+F37*(1-F38-F39) -> 0.5 | I40: =1-I37+I37*(1-I38-I39) -> 0.2 | L40: =1-L37+L37*(1-L38-L39) -> #N/A | O40: =1-O37+O37*(1-O38-O39) -> #N/A | R40: =1-R37+R37*(1-R38-R39) -> #N/A
C42: recyclability | D42: overall | E42: - | F42: =(F32*F33*F28+F37*F38)/(1+F28) -> 0 | I42: =(I32*I33*I28+I37*I38)/(1+I28) -> 0 | L42: =(L32*L33*L28+L37*L38)/(1+L28) -> #N/A | O42: =(O32*O33*O28+O37*O38)/(1+O28) -> #N/A | R42: =(R32*R33*R28+R37*R38)/(1+R28) -> #N/A
C43: cascadability | D43: overall | E43: - | F43: =(F32*F34*F28+F37*F39)/(1+F28) -> 0.53636364 | I43: =(I32*I34*I28+I37*I39)/(1+I28) -> 0.80909091 | L43: =(L32*L34*L28+L37*L39)/(1+L28) -> #N/A | O43: =(O32*O34*O28+O37*O39)/(1+O28) -> #N/A | R43: =(R32*R34*R28+R37*R39)/(1+R28) -> #N/A
C44: final loss | D44: overall | E44: - | F44: =1-F42-F43 -> 0.46363636 | I44: =1-I42-I43 -> 0.19090909 | L44: =1-L42-L43 -> #N/A | O44: =1-O42-O43 -> #N/A | R44: =1-R42-R43 -> #N/A
B46: τ | C46: ressource pressure | D46: base material | E46: - | F46: =(0.5*F27/F22)*(1+F28)*(1/lifetime_concrete)*(1+F24*(1-F42)-F42-F43) -> 2.5957925e-12 | I46: =(0.5*I27/I22)*(1+I28)*(1/lifetime_concrete)*(1+I24*(1-I42)-I42-I43) -> 2.1121044e-12 | L46: =(0.5*L27/L22)*(1+L28)*(1/lifetime_concrete)*(1+L24*(1-L42)-L42-L43) -> #N/A | O46: =(0.5*O27/O22)*(1+O28)*(1/lifetime_concrete)*(1+O24*(1-O42)-O42-O43) -> #N/A | R46: =(0.5*R27/R22)*(1+R28)*(1/lifetime_concrete)*(1+R24*(1-R42)-R42-R43) -> #N/A
A49: bulk material 2 | B49: mat | C49: material | D49: ERP identifier | F49: =INDEX(tbl_material[],MATCH(F$11,tbl_material[ERP identifier],0),MATCH(RP_concrete!$D$49,tbl_material[#Headers],0)) -> gravel | I49: =INDEX(tbl_material[],MATCH(I$11,tbl_material[ERP identifier],0),MATCH(RP_concrete!$D$49,tbl_material[#Headers],0)) -> gravel | L49: =INDEX(tbl_material[],MATCH(L$11,tbl_material[ERP identifier],0),MATCH(RP_concrete!$D$49,tbl_material[#Headers],0)) -> #N/A | O49: =INDEX(tbl_material[],MATCH(O$11,tbl_material[ERP identifier],0),MATCH(RP_concrete!$D$49,tbl_material[#Headers],0)) -> #N/A | R49: =INDEX(tbl_material[],MATCH(R$11,tbl_material[ERP identifier],0),MATCH(RP_concrete!$D$49,tbl_material[#Headers],0)) -> #N/A
...

Sheet RP_SICUT
A1: Resource Pressure Calculation
A3: SICUT | D3: option | F3: si_01 | I3: si_02 | L3: si_03 | O3: si_04 | R3: si_05
D4: description | F4: SICUT basic 20 Jahre | I4: SICUT green 20 Jahre | L4: SICUT green 30 Jahre | O4: SICUT green 40 Jahre | R4: SICUT basic 40 Jahre
D5: primary material content | F5: basic_primary material content | I5: green_primary material content | L5: green_primary material content | O5: green_primary material content | R5: basic_primary material content
D6: collection rate of EoL sleeper materials | F6: basic_collection rate | I6: green_collection rate | L6: green_collection rate | O6: green_collection rate | R6: basic_collection rate
D7: recycling rate of collected EoL sleeper materials | F7: basic_recycling rate | I7: green_recycling rate | L7: green_recycling rate | O7: green_recycling rate | R7: basic_recycling rate
D8: cascading rate of collected EoL sleeper materials | F8: basic_cascading rate | I8: green_cascading rate | L8: green_cascading rate | O8: green_cascading rate | R8: basic_cascading rate
G9: τ | J9: τ | M9: τ | P9: τ | S9: τ
D10: bulk material | F10: PET | G10: =F46 -> 9.2134869e-12 | I10: PET | J10: =I46 -> 1.0034491e-12 | L10: PET | M10: =L46 -> 6.6896604e-13 | O10: PET | P10: =O46 -> 5.0172453e-13 | R10: PET | S10: =R46 -> 4.6067434e-12
D11: reinforcement | F11: glass fibre | G11: =F74 -> 2.6448778e-12 | I11: glass fibre | J11: =I74 -> 4.7791108e-13 | L11: glass fibre | M11: =L74 -> 3.1860739e-13 | O11: glass fibre | P11: =O74 -> 2.3895554e-13 | R11: glass fibre | S11: =R74 -> 1.3224389e-12
D12: electricity | F12: basic | G12: =F95 -> 2.4050663e-12 | I12: basic | J12: =I95 -> 2.4050663e-12 | L12: basic | M12: =L95 -> 1.6033776e-12 | O12: basic | P12: =O95 -> 1.2025332e-12 | R12: basic | S12: =R95 -> 1.2025332e-12
D13: heat | F13: basic | G13: =F110 -> 1.5468077e-13 | I13: basic | J13: =I110 -> 1.5468077e-13 | L13: basic | M13: =L110 -> 1.0312051e-13 | O13: basic | P13: =O110 -> 7.7340384e-14 | R13: basic | S13: =R110 -> 7.7340384e-14
D14: transport land | F14: basic_land | G14: =F124 -> 5.7119916e-14 | I14: basic_land | J14: =I124 -> 5.7119916e-14 | L14: basic_land | M14: =L124 -> 3.8079944e-14 | O14: basic_land | P14: =O124 -> 2.8559958e-14 | R14: basic_land | S14: =R124 -> 2.8559958e-14
D15: transport overseas | F15: basic_overseas | G15: =F137 -> 0 | I15: basic_overseas | J15: =I137 -> 0 | L15: basic_overseas | M15: =L137 -> 0 | O15: basic_overseas | P15: =O137 -> 0 | R15: basic_overseas | S15: =R137 -> 0
D16: ressource pressure | G16: =SUM(G10:G15) -> 1.4475232e-11 | J16: =SUM(J10:J15) -> 4.0982272e-12 | M16: =SUM(M10:M15) -> 2.7321514e-12 | P16: =SUM(P10:P15) -> 2.0491136e-12 | S16: =SUM(S10:S15) -> 7.2376158e-12
B17: Input cell
A18: aspect | B18: icon | C18: name | D18: description | E18: unit
B19: #VALUE! | C19: Life Time | D19: Use phase duration | E19: year | F19: 20 | I19: 20 | L19: 30 | O19: 40 | R19: 40
A21: bulk material | B21: mat | C21: material | D21: ERP identifier | F21: =INDEX(tbl_material[],MATCH(F$10,tbl_material[ERP identifier],0),MATCH(RP_SICUT!$D$21,tbl_material[#Headers],0)) -> PET | I21: =INDEX(tbl_material[],MATCH(I$10,tbl_material[ERP identifier],0),MATCH(RP_SICUT!$D$21,tbl_material[#Headers],0)) -> PET | L21: =INDEX(tbl_material[],MATCH(L$10,tbl_material[ERP identifier],0),MATCH(RP_SICUT!$D$21,tbl_material[#Headers],0)) -> PET | O21: =INDEX(tbl_material[],MATCH(O$10,tbl_material[ERP identifier],0),MATCH(RP_SICUT!$D$21,tbl_material[#Headers],0)) -> PET | R21: =INDEX(tbl_material[],MATCH(R$10,tbl_material[ERP identifier],0),MATCH(RP_SICUT!$D$21,tbl_material[#Headers],0)) -> PET
B22: ERP | C22: Environmental Ressource Potential | D22: ERP effective [FU/a] | E22: kg/a | F22: =INDEX(tbl_ERP[],MATCH(F21,tbl_ERP[Identifier],0),MATCH(RP_SICUT!$D$22,tbl_ERP[#Headers],0)) -> 1.781356e+11 | I22: =INDEX(tbl_ERP[],MATCH(I21,tbl_ERP[Identifier],0),MATCH(RP_SICUT!$D$22,tbl_ERP[#Headers],0)) -> 1.781356e+11 | L22: =INDEX(tbl_ERP[],MATCH(L21,tbl_ERP[Identifier],0),MATCH(RP_SICUT!$D$22,tbl_ERP[#Headers],0)) -> 1.781356e+11 | O22: =INDEX(tbl_ERP[],MATCH(O21,tbl_ERP[Identifier],0),MATCH(RP_SICUT!$D$22,tbl_ERP[#Headers],0)) -> 1.781356e+11 | R22: =INDEX(tbl_ERP[],MATCH(R21,tbl_ERP[Identifier],0),MATCH(RP_SICUT!$D$22,tbl_ERP[#Headers],0)) -> 1.781356e+11
C24: primary material content | D24: per input (primary and secondary) without recycling | E24: - | F24: =INDEX(tbl_material[],MATCH(F$10,tbl_material[material],0),MATCH(RP_SICUT!$F$5,tbl_material[#Headers],0)) -> 0 | I24: =INDEX(tbl_material[],MATCH(I$10,tbl_material[material],0),MATCH(RP_SICUT!I$5,tbl_material[#Headers],0)) -> 0 | L24: =INDEX(tbl_material[],MATCH(L$10,tbl_material[material],0),MATCH(RP_SICUT!L$5,tbl_material[#Headers],0)) -> 0 | O24: =INDEX(tbl_material[],MATCH(O$10,tbl_material[material],0),MATCH(RP_SICUT!O$5,tbl_material[#Headers],0)) -> 0 | R24: =INDEX(tbl_material[],MATCH(R$10,tbl_material[material],0),MATCH(RP_SICUT!R$5,tbl_material[#Headers],0)) -> 0
C25: secondary material content | D25: per input (primary and secondary) without recycling | E25: - | F25: =1-F24 -> 1 | I25: =1-I24 -> 1 | L25: =1-L24 -> 1 | O25: =1-O24 -> 1 | R25: =1-R24 -> 1
C27: mass | D27: per sleeper | E27: kg | F27: =INDEX(tbl_material[],MATCH(F$10,tbl_material[material],0),MATCH(RP_SICUT!$C$27,tbl_material[#Headers],0)) -> 65 | I27: =INDEX(tbl_material[],MATCH(I$10,tbl_material[material],0),MATCH(RP_SICUT!$C$27,tbl_material[#Headers],0)) -> 65 | L27: =INDEX(tbl_material[],MATCH(L$10,tbl_material[material],0),MATCH(RP_SICUT!$C$27,tbl_material[#Headers],0)) -> 65 | O27: =INDEX(tbl_material[],MATCH(O$10,tbl_material[material],0),MATCH(RP_SICUT!$C$27,tbl_material[#Headers],0)) -> 65 | R27: =INDEX(tbl_material[],MATCH(R$10,tbl_material[material],0),MATCH(RP_SICUT!$C$27,tbl_material[#Headers],0)) -> 65
C28: manufacturing losses | D28: in relation to product | E28: - | F28: =INDEX(tbl_material[],MATCH(F$10,tbl_material[material],0),MATCH(RP_SICUT!$C$28,tbl_material[#Headers],0)) -> 0.1 | I28: =INDEX(tbl_material[],MATCH(I$10,tbl_material[material],0),MATCH(RP_SICUT!$C$28,tbl_material[#Headers],0)) -> 0.1 | L28: =INDEX(tbl_material[],MATCH(L$10,tbl_material[material],0),MATCH(RP_SICUT!$C$28,tbl_material[#Headers],0)) -> 0.1 | O28: =INDEX(tbl_material[],MATCH(O$10,tbl_material[material],0),MATCH(RP_SICUT!$C$28,tbl_material[#Headers],0)) -> 0.1 | R28: =INDEX(tbl_material[],MATCH(R$10,tbl_material[material],0),MATCH(RP_SICUT!$C$28,tbl_material[#Headers],0)) -> 0.1
C29: manufacturing losses | D29: per product | E29: kg | F29: =F27*F28 -> 6.5 | I29: =I27*I28 -> 6.5 | L29: =L27*L28 -> 6.5 | O29: =O27*O28 -> 6.5 | R29: =R27*R28 -> 6.5
C30: mass required | D30: per product | E30: kg | F30: =F27*(1+F28) -> 71.5 | I30: =I27*(1+I28) -> 71.5 | L30: =L27*(1+L28) -> 71.5 | O30: =O27*(1+O28) -> 71.5 | R30: =R27*(1+R28) -> 71.5
C32: collection rate | D32: of manufacturing losses | E32: - | F32: =INDEX(tbl_material[],MATCH(F$10,tbl_material[material],0),MATCH(RP_SICUT!$C$32,tbl_material[#Headers],0)) -> 1 | I32: =INDEX(tbl_material[],MATCH(I$10,tbl_material[material],0),MATCH(RP_SICUT!$C$32,tbl_material[#Headers],0)) -> 1 | L32: =INDEX(tbl_material[],MATCH(L$10,tbl_material[material],0),MATCH(RP_SICUT!$C$32,tbl_material[#Headers],0)) -> 1 | O32: =INDEX(tbl_material[],MATCH(O$10,tbl_material[material],0),MATCH(RP_SICUT!$C$32,tbl_material[#Headers],0)) -> 1 | R32: =INDEX(tbl_material[],MATCH(R$10,tbl_material[material],0),MATCH(RP_SICUT!$C$32,tbl_material[#Headers],0)) -> 1
C33: recycling rate | D33: of collected manufacturing losses | E33: - | F33: =INDEX(tbl_material[],MATCH(F$10,tbl_material[material],0),MATCH(RP_SICUT!$C$33,tbl_material[#Headers],0)) -> 0.9 | I33: =INDEX(tbl_material[],MATCH(I$10,tbl_material[material],0),MATCH(RP_SICUT!$C$33,tbl_material[#Headers],0)) -> 0.9 | L33: =INDEX(tbl_material[],MATCH(L$10,tbl_material[material],0),MATCH(RP_SICUT!$C$33,tbl_material[#Headers],0)) -> 0.9 | O33: =INDEX(tbl_material[],MATCH(O$10,tbl_material[material],0),MATCH(RP_SICUT!$C$33,tbl_material[#Headers],0)) -> 0.9 | R33: =INDEX(tbl_material[],MATCH(R$10,tbl_material[material],0),MATCH(RP_SICUT!$C$33,tbl_material[#Headers],0)) -> 0.9
C34: cascading rate | D34: of collected manufacturing losses | E34: - | F34: =INDEX(tbl_material[],MATCH(F$10,tbl_material[material],0),MATCH(RP_SICUT!$C$34,tbl_material[#Headers],0)) -> 0 | I34: =INDEX(tbl_material[],MATCH(I$10,tbl_material[material],0),MATCH(RP_SICUT!$C$34,tbl_material[#Headers],0)) -> 0 | L34: =INDEX(tbl_material[],MATCH(L$10,tbl_material[material],0),MATCH(RP_SICUT!$C$34,tbl_material[#Headers],0)) -> 0 | O34: =INDEX(tbl_material[],MATCH(O$10,tbl_material[material],0),MATCH(RP_SICUT!$C$34,tbl_material[#Headers],0)) -> 0 | R34: =INDEX(tbl_material[],MATCH(R$10,tbl_material[material],0),MATCH(RP_SICUT!$C$34,tbl_material[#Headers],0)) -> 0
C35: loss rate | D35: of collected manufacturing losses | E35: - | F35: =1-F32+F32*(1-F33-F34) -> 0.1 | I35: =1-I32+I32*(1-I33-I34) -> 0.1 | L35: =1-L32+L32*(1-L33-L34) -> 0.1 | O35: =1-O32+O32*(1-O33-O34) -> 0.1 | R35: =1-R32+R32*(1-R33-R34) -> 0.1
C37: collection rate | D37: of EoL products | E37: - | F37: =INDEX(tbl_material[],MATCH(F$10,tbl_material[material],0),MATCH(RP_SICUT!$F$6,tbl_material[#Headers],0)) -> 1 | I37: =INDEX(tbl_material[],MATCH(I$10,tbl_material[material],0),MATCH(RP_SICUT!I$6,tbl_material[#Headers],0)) -> 1 | L37: =INDEX(tbl_material[],MATCH(L$10,tbl_material[material],0),MATCH(RP_SICUT!L$6,tbl_material[#Headers],0)) -> 1 | O37: =INDEX(tbl_material[],MATCH(O$10,tbl_material[material],0),MATCH(RP_SICUT!O$6,tbl_material[#Headers],0)) -> 1 | R37: =INDEX(tbl_material[],MATCH(R$10,tbl_material[material],0),MATCH(RP_SICUT!R$6,tbl_material[#Headers],0)) -> 1
C38: recycling rate | D38: of collected EoL products (base material) | E38: - | F38: =INDEX(tbl_material[],MATCH(F$10,tbl_material[material],0),MATCH(RP_SICUT!$F$7,tbl_material[#Headers],0)) -> 0 | I38: =INDEX(tbl_material[],MATCH(I$10,tbl_material[material],0),MATCH(RP_SICUT!$I$7,tbl_material[#Headers],0)) -> 0.5 | L38: =INDEX(tbl_material[],MATCH(L$10,tbl_material[material],0),MATCH(RP_SICUT!$L$7,tbl_material[#Headers],0)) -> 0.5 | O38: =INDEX(tbl_material[],MATCH(O$10,tbl_material[material],0),MATCH(RP_SICUT!$O$7,tbl_material[#Headers],0)) -> 0.5 | R38: =INDEX(tbl_material[],MATCH(R$10,tbl_material[material],0),MATCH(RP_SICUT!R$7,tbl_material[#Headers],0)) -> 0
C39: cascading rate | D39: of collected EoL products (base material) | E39: - | F39: =INDEX(tbl_material[],MATCH(F$10,tbl_material[material],0),MATCH(RP_SICUT!$F$8,tbl_material[#Headers],0)) -> 0 | I39: =INDEX(tbl_material[],MATCH(I$10,tbl_material[material],0),MATCH(RP_SICUT!I$8,tbl_material[#Headers],0)) -> 0.4 | L39: =INDEX(tbl_material[],MATCH(L$10,tbl_material[material],0),MATCH(RP_SICUT!L$8,tbl_material[#Headers],0)) -> 0.4 | O39: =INDEX(tbl_material[],MATCH(O$10,tbl_material[material],0),MATCH(RP_SICUT!O$8,tbl_material[#Headers],0)) -> 0.4 | R39: =INDEX(tbl_material[],MATCH(R$10,tbl_material[material],0),MATCH(RP_SICUT!R$8,tbl_material[#Headers],0)) -> 0
C40: loss rate | D40: of collected EoL products (base material) | E40: - | F40: =1-F37+F37*(1-F38-F39) -> 1 | I40: =1-I37+I37*(1-I38-I39) -> 0.1 | L40: =1-L37+L37*(1-L38-L39) -> 0.1 | O40: =1-O37+O37*(1-O38-O39) -> 0.1 | R40: =1-R37+R37*(1-R38-R39) -> 1
C42: recyclability | D42: overall | E42: - | F42: =(F32*F33*F28+F37*F38)/(1+F28) -> 0.081818182 | I42: =(I32*I33*I28+I37*I38)/(1+I28) -> 0.53636364 | L42: =(L32*L33*L28+L37*L38)/(1+L28) -> 0.53636364 | O42: =(O32*O33*O28+O37*O38)/(1+O28) -> 0.53636364 | R42: =(R32*R33*R28+R37*R38)/(1+R28) -> 0.081818182
C43: cascadability | D43: overall | E43: - | F43: =(F32*F34*F28+F37*F39)/(1+F28) -> 0 | I43: =(I32*I34*I28+I37*I39)/(1+I28) -> 0.36363636 | L43: =(L32*L34*L28+L37*L39)/(1+L28) -> 0.36363636 | O43: =(O32*O34*O28+O37*O39)/(1+O28) -> 0.36363636 | R43: =(R32*R34*R28+R37*R39)/(1+R28) -> 0
C44: final loss | D44: overall | E44: - | F44: =1-F42-F43 -> 0.91818182 | I44: =1-I42-I43 -> 0.1 | L44: =1-L42-L43 -> 0.1 | O44: =1-O42-O43 -> 0.1 | R44: =1-R42-R43 -> 0.91818182
B46: τ | C46: ressource pressure | D46: base material | E46: - | F46: =(0.5*F27/F22)*(1+F28)*(1/F19)*(1+F24*(1-F42)-F42-F43) -> 9.2134869e-12 | I46: =(0.5*I27/I22)*(1+I28)*(1/I19)*(1+I24*(1-I42)-I42-I43) -> 1.0034491e-12 | L46: =(0.5*L27/L22)*(1+L28)*(1/L19)*(1+L24*(1-L42)-L42-L43) -> 6.6896604e-13 | O46: =(0.5*O27/O22)*(1+O28)*(1/O19)*(1+O24*(1-O42)-O42-O43) -> 5.0172453e-13 | R46: =(0.5*R27/R22)*(1+R28)*(1/R19)*(1+R24*(1-R42)-R42-R43) -> 4.6067434e-12
A49: reinforcement | B49: mat | C49: material | D49: ERP identifier | F49: =INDEX(tbl_material[],MATCH(F$11,tbl_material[ERP identifier],0),MATCH(RP_SICUT!$D$49,tbl_material[#Headers],0)) -> glass fibre | I49: =INDEX(tbl_material[],MATCH(I$11,tbl_material[ERP identifier],0),MATCH(RP_SICUT!$D$49,tbl_material[#Headers],0)) -> glass fibre | L49: =INDEX(tbl_material[],MATCH(L$11,tbl_material[ERP identifier],0),MATCH(RP_SICUT!$D$49,tbl_material[#Headers],0)) -> glass fibre | O49: =INDEX(tbl_material[],MATCH(O$11,tbl_material[ERP identifier],0),MATCH(RP_SICUT!$D$49,tbl_material[#Headers],0)) -> glass fibre | R49: =INDEX(tbl_material[],MATCH(R$11,tbl_material[ERP identifier],0),MATCH(RP_SICUT!$D$49,tbl_material[#Headers],0)) -> glass fibre
B50: ERP | C50: Environmental Ressource Potential | D50: ERP effective [FU/a] | E50: kg/a | F50: =INDEX(tbl_ERP[],MATCH(F49,tbl_ERP[Identifier],0),MATCH(RP_SICUT!$D$50,tbl_ERP[#Headers],0)) -> 3.818702e+11 | I50: =INDEX(tbl_ERP[],MATCH(I49,tbl_ERP[Identifier],0),MATCH(RP_SICUT!$D$50,tbl_ERP[#Headers],0)) -> 3.818702e+11 | L50: =INDEX(tbl_ERP[],MATCH(L49,tbl_ERP[Identifier],0),MATCH(RP_SICUT!$D$50,tbl_ERP[#Headers],0)) -> 3.818702e+11 | O50: =INDEX(tbl_ERP[],MATCH(O49,tbl_ERP[Identifier],0),MATCH(RP_SICUT!$D$50,tbl_ERP[#Headers],0)) -> 3.818702e+11 | R50: =INDEX(tbl_ERP[],MATCH(R49,tbl_ERP[Identifier],0),MATCH(RP_SICUT!$D$50,tbl_ERP[#Headers],0)) -> 3.818702e+11
...
